Traceback (most recent call last):
  File "C:\ProgramData\Anaconda3\envs\dsm_book\lib\site-packages\jupyter_cache\executors\utils.py", line 51, in single_nb_execution
    executenb(
  File "C:\ProgramData\Anaconda3\envs\dsm_book\lib\site-packages\nbclient\client.py", line 1112, in execute
    return NotebookClient(nb=nb, resources=resources, km=km, **kwargs).execute()
  File "C:\ProgramData\Anaconda3\envs\dsm_book\lib\site-packages\nbclient\util.py", line 74, in wrapped
    return just_run(coro(*args, **kwargs))
  File "C:\ProgramData\Anaconda3\envs\dsm_book\lib\site-packages\nbclient\util.py", line 53, in just_run
    return loop.run_until_complete(coro)
  File "C:\ProgramData\Anaconda3\envs\dsm_book\lib\asyncio\base_events.py", line 616, in run_until_complete
    return future.result()
  File "C:\ProgramData\Anaconda3\envs\dsm_book\lib\site-packages\nbclient\client.py", line 553, in async_execute
    await self.async_execute_cell(
  File "C:\ProgramData\Anaconda3\envs\dsm_book\lib\site-packages\nbclient\client.py", line 857, in async_execute_cell
    self._check_raise_for_error(cell, exec_reply)
  File "C:\ProgramData\Anaconda3\envs\dsm_book\lib\site-packages\nbclient\client.py", line 760, in _check_raise_for_error
    raise CellExecutionError.from_cell_and_msg(cell, exec_reply_content)
nbclient.exceptions.CellExecutionError: An error occurred while executing the following cell:
------------------
modelRF <- randomForest(churn ~ ., data = churn, importance=TRUE)
------------------

Error in randomForest.default(m, y, ...): NA/NaN/Inf in foreign function call (arg 1)
Traceback:

1. randomForest(churn ~ ., data = churn, importance = TRUE)
2. randomForest.formula(churn ~ ., data = churn, importance = TRUE)
3. randomForest.default(m, y, ...)
ERROR: Error in randomForest.default(m, y, ...): NA/NaN/Inf in foreign function call (arg 1)


